0,SyntaxError,"expected ':' (3757715804.py, line 1)",0,,2024-10-10 14:30:12.108437,"[('return compile(source, filename, symbol, self.flags | PyCF_ONLY_AST, 1)', 86)]","['Traceback (most recent call last):', '  File ""/home/luohan/anaconda3/envs/data8/lib/python3.10/site-packages/IPython/core/interactiveshell.py"", line 3306, in run_cell_async', '    code_ast = compiler.ast_parse(cell, filename=cell_name)', '  File ""/home/luohan/anaconda3/envs/data8/lib/python3.10/site-packages/IPython/core/compilerop.py"", line 86, in ast_parse', '    return compile(source, filename, symbol, self.flags | PyCF_ONLY_AST, 1)', '  File ""/tmp/ipykernel_151/3757715804.py"", line 1', '    def to_percentage(num)', '                          ^', ""SyntaxError: expected ':'""]"
1,NameError,name 'factor' is not defined,0,,2024-10-10 14:30:31.126010,"[('factor', 3)]","['Traceback (most recent call last):', '  File ""/home/luohan/anaconda3/envs/data8/lib/python3.10/site-packages/IPython/core/interactiveshell.py"", line 3577, in run_code', '    exec(code_obj, self.user_global_ns, self.user_ns)', '  File ""/tmp/ipykernel_151/3742982240.py"", line 3, in <module>', '    factor', ""NameError: name 'factor' is not defined""]"
2,TypeError,unsupported operand type(s) for +: 'NoneType' and 'int',0,,2024-10-10 14:41:37.851766,"[('print_number_five_output + 2', 2)]","['Traceback (most recent call last):', '  File ""/home/luohan/anaconda3/envs/data8/lib/python3.10/site-packages/IPython/core/interactiveshell.py"", line 3577, in run_code', '    exec(code_obj, self.user_global_ns, self.user_ns)', '  File ""/tmp/ipykernel_151/55797484.py"", line 2, in <module>', '    print_number_five_output + 2', ""TypeError: unsupported operand type(s) for +: 'NoneType' and 'int'""]"
3,TypeError,"the resolved dtypes are not compatible with add.reduce. Resolved (dtype('<U7'), dtype('<U7'), dtype('<U14'))",0,,2024-10-10 14:43:17.849624,"[('np.average(raw_compensation.column(""Total Pay""))', 1), ('avg = a.mean(axis, **keepdims_kw)', 562)]","['Traceback (most recent call last):', '  File ""/home/luohan/anaconda3/envs/data8/lib/python3.10/site-packages/IPython/core/interactiveshell.py"", line 3577, in run_code', '    exec(code_obj, self.user_global_ns, self.user_ns)', '  File ""/tmp/ipykernel_151/1172901112.py"", line 1, in <module>', '    np.average(raw_compensation.column(""Total Pay""))', '  File ""/home/luohan/anaconda3/envs/data8/lib/python3.10/site-packages/numpy/lib/_function_base_impl.py"", line 562, in average', '    avg = a.mean(axis, **keepdims_kw)', '  File ""/home/luohan/anaconda3/envs/data8/lib/python3.10/site-packages/numpy/_core/_methods.py"", line 136, in _mean', '    ret = umr_sum(arr, axis, dtype, out, keepdims, where=where)', ""TypeError: the resolved dtypes are not compatible with add.reduce. Resolved (dtype('<U7'), dtype('<U7'), dtype('<U14'))""]"
4,TypeError,'int' object is not callable,0,,2024-10-10 14:50:46.283891,"[('max(2, 6)', 2)]","['Traceback (most recent call last):', '  File ""/home/luohan/anaconda3/envs/data8/lib/python3.10/site-packages/IPython/core/interactiveshell.py"", line 3577, in run_code', '    exec(code_obj, self.user_global_ns, self.user_ns)', '  File ""/tmp/ipykernel_151/2218400260.py"", line 2, in <module>', '    max(2, 6)', ""TypeError: 'int' object is not callable""]"
