0,ValueError,"The column ""NEI_PTER"" is not in the table. The table contains these columns: Date, NEI, NEI-PTER",0,,2024-10-09 20:41:55.945653,"[('""PTER"",unemployment.column(""NEI_PTER"")-unemployment.column(""NEI"")', 3), ('raise ValueError(', 448)]","['Traceback (most recent call last):', '  File ""/home/luohan/anaconda3/envs/data8/lib/python3.10/site-packages/IPython/core/interactiveshell.py"", line 3577, in run_code', '    exec(code_obj, self.user_global_ns, self.user_ns)', '  File ""/tmp/ipykernel_132/1226275505.py"", line 3, in <module>', '    ""PTER"",unemployment.column(""NEI_PTER"")-unemployment.column(""NEI"")', '  File ""/home/luohan/anaconda3/envs/data8/lib/python3.10/site-packages/datascience/tables.py"", line 448, in column', '    raise ValueError(', 'ValueError: The column ""NEI_PTER"" is not in the table. The table contains these columns: Date, NEI, NEI-PTER']"
1,TypeError,'collections.deque' object is not callable,0,,2024-10-09 20:58:42.574316,"[('pter_over_time.plots(""Year"",""PTER"")', 6)]","['Traceback (most recent call last):', '  File ""/home/luohan/anaconda3/envs/data8/lib/python3.10/site-packages/IPython/core/interactiveshell.py"", line 3577, in run_code', '    exec(code_obj, self.user_global_ns, self.user_ns)', '  File ""/tmp/ipykernel_132/2692562560.py"", line 6, in <module>', '    pter_over_time.plots(""Year"",""PTER"")', ""TypeError: 'collections.deque' object is not callable""]"
2,TypeError,'collections.deque' object is not callable,0,,2024-10-09 21:01:48.706853,"[('pter_over_time.plots(""Year"", ""PTER"")', 6)]","['Traceback (most recent call last):', '  File ""/home/luohan/anaconda3/envs/data8/lib/python3.10/site-packages/IPython/core/interactiveshell.py"", line 3577, in run_code', '    exec(code_obj, self.user_global_ns, self.user_ns)', '  File ""/tmp/ipykernel_132/3257740341.py"", line 6, in <module>', '    pter_over_time.plots(""Year"", ""PTER"")', ""TypeError: 'collections.deque' object is not callable""]"
3,TypeError,'collections.deque' object is not callable,0,,2024-10-09 21:04:04.825988,"[('pter_over_time.plots(""Year"", ""PTER"")', 7)]","['Traceback (most recent call last):', '  File ""/home/luohan/anaconda3/envs/data8/lib/python3.10/site-packages/IPython/core/interactiveshell.py"", line 3577, in run_code', '    exec(code_obj, self.user_global_ns, self.user_ns)', '  File ""/tmp/ipykernel_132/718291432.py"", line 7, in <module>', '    pter_over_time.plots(""Year"", ""PTER"")', ""TypeError: 'collections.deque' object is not callable""]"
4,TypeError,'collections.deque' object is not callable,0,,2024-10-09 21:05:32.109178,"[('pter_over_time.plots(""Year"", ""PTER"")', 7)]","['Traceback (most recent call last):', '  File ""/home/luohan/anaconda3/envs/data8/lib/python3.10/site-packages/IPython/core/interactiveshell.py"", line 3577, in run_code', '    exec(code_obj, self.user_global_ns, self.user_ns)', '  File ""/tmp/ipykernel_132/3969037976.py"", line 7, in <module>', '    pter_over_time.plots(""Year"", ""PTER"")', ""TypeError: 'collections.deque' object is not callable""]"
5,SyntaxError,"invalid syntax (1997731869.py, line 2)",0,,2024-10-09 21:22:31.972167,"[('return compile(source, filename, symbol, self.flags | PyCF_ONLY_AST, 1)', 86)]","['Traceback (most recent call last):', '  File ""/home/luohan/anaconda3/envs/data8/lib/python3.10/site-packages/IPython/core/interactiveshell.py"", line 3306, in run_cell_async', '    code_ast = compiler.ast_parse(cell, filename=cell_name)', '  File ""/home/luohan/anaconda3/envs/data8/lib/python3.10/site-packages/IPython/core/compilerop.py"", line 86, in ast_parse', '    return compile(source, filename, symbol, self.flags | PyCF_ONLY_AST, 1)', '  File ""/tmp/ipykernel_132/1997731869.py"", line 2', '    movers = migration_rates.where(mig,are.above(1%)).num_rows', '                                                   ^', 'SyntaxError: invalid syntax']"
6,SyntaxError,"invalid syntax (2872853246.py, line 2)",0,,2024-10-09 21:22:56.202896,"[('return compile(source, filename, symbol, self.flags | PyCF_ONLY_AST, 1)', 86)]","['Traceback (most recent call last):', '  File ""/home/luohan/anaconda3/envs/data8/lib/python3.10/site-packages/IPython/core/interactiveshell.py"", line 3306, in run_cell_async', '    code_ast = compiler.ast_parse(cell, filename=cell_name)', '  File ""/home/luohan/anaconda3/envs/data8/lib/python3.10/site-packages/IPython/core/compilerop.py"", line 86, in ast_parse', '    return compile(source, filename, symbol, self.flags | PyCF_ONLY_AST, 1)', '  File ""/tmp/ipykernel_132/2872853246.py"", line 2', ""    movers = migration_rates.where('mig',are.above(1%)).num_rows"", '                                                     ^', 'SyntaxError: invalid syntax']"
7,AssertionError,column length mismatch,0,,2024-10-09 21:35:10.297881,"[('Table().scatter(birth_rates,death_rates)', 4), ('x_data, y_labels =  self._split_column_and_labels(column_for_x)', 4066)]","['Traceback (most recent call last):', '  File ""/home/luohan/anaconda3/envs/data8/lib/python3.10/site-packages/IPython/core/interactiveshell.py"", line 3577, in run_code', '    exec(code_obj, self.user_global_ns, self.user_ns)', '  File ""/tmp/ipykernel_132/2635302334.py"", line 4, in <module>', '    Table().scatter(birth_rates,death_rates)', '  File ""/home/luohan/anaconda3/envs/data8/lib/python3.10/site-packages/datascience/tables.py"", line 4066, in scatter', '    x_data, y_labels =  self._split_column_and_labels(column_for_x)', '  File ""/home/luohan/anaconda3/envs/data8/lib/python3.10/site-packages/datascience/tables.py"", line 4719, in _split_column_and_labels', '    column = None if column_or_label is None else self._get_column(column_or_label)', '  File ""/home/luohan/anaconda3/envs/data8/lib/python3.10/site-packages/datascience/tables.py"", line 2231, in _get_column', ""    assert len(c) == self.num_rows, 'column length mismatch'"", 'AssertionError: column length mismatch']"
